# Logfile created on 2018-05-02 17:25:10 by logger.rb/47272
I, [2018-05-02T17:25:10.355806 #2734]  INFO -- : *** below you find the most recent exception thrown, this will be likely (but not certainly) the exception that made the application exit abnormally ***
E, [2018-05-02T17:25:10.356124 #2734] ERROR -- : No such file or directory @ rb_sysopen - /Users/yyong/rbdev/peatio/log/payment_transaction.rb.log (Errno::ENOENT)
/Users/yyong/.rbenv/versions/2.2.1/lib/ruby/2.2.0/open-uri.rb:36:in `initialize'
/Users/yyong/.rbenv/versions/2.2.1/lib/ruby/2.2.0/open-uri.rb:36:in `open'
/Users/yyong/.rbenv/versions/2.2.1/lib/ruby/2.2.0/open-uri.rb:36:in `open'
/Users/yyong/.rbenv/versions/2.2.1/lib/ruby/2.2.0/logger.rb:628:in `open_logfile'
/Users/yyong/.rbenv/versions/2.2.1/lib/ruby/2.2.0/logger.rb:584:in `initialize'
/Users/yyong/.rbenv/versions/2.2.1/lib/ruby/2.2.0/logger.rb:318:in `new'
/Users/yyong/.rbenv/versions/2.2.1/lib/ruby/2.2.0/logger.rb:318:in `initialize'
/Users/yyong/.rbenv/versions/2.2.1/lib/ruby/gems/2.2.0/gems/daemons-1.1.9/lib/daemons/application.rb:353:in `new'
/Users/yyong/.rbenv/versions/2.2.1/lib/ruby/gems/2.2.0/gems/daemons-1.1.9/lib/daemons/application.rb:353:in `exception_log'
/Users/yyong/.rbenv/versions/2.2.1/lib/ruby/gems/2.2.0/gems/daemons-1.1.9/lib/daemons/application.rb:165:in `block in start_load'
I, [2018-05-02T17:25:10.356277 #2734]  INFO -- : *** below you find all exception objects found in memory, some of them may have been thrown in your application, others may just be in memory because they are standard exceptions ***
E, [2018-05-02T17:25:10.362902 #2734] ERROR -- : stream closed (IOError)

E, [2018-05-02T17:25:10.364171 #2734] ERROR -- : failed to allocate memory (NoMemoryError)

E, [2018-05-02T17:25:10.364334 #2734] ERROR -- : stack level too deep (SystemStackError)

E, [2018-05-02T17:25:10.364710 #2734] ERROR -- : exception reentered (fatal)

E, [2018-05-02T17:25:10.431571 #2734] ERROR -- : Value will be available once the pipeline executes. (Redis::FutureNotReady)

E, [2018-05-02T17:25:10.468482 #2734] ERROR -- : no such frame (ArgumentError)
/Users/yyong/.rbenv/versions/2.2.1/lib/ruby/gems/2.2.0/gems/binding_of_caller-0.7.2/lib/binding_of_caller/mri2.rb:25:in `frame_binding'
/Users/yyong/.rbenv/versions/2.2.1/lib/ruby/gems/2.2.0/gems/binding_of_caller-0.7.2/lib/binding_of_caller/mri2.rb:25:in `block (2 levels) in callers'
/Users/yyong/.rbenv/versions/2.2.1/lib/ruby/gems/2.2.0/gems/binding_of_caller-0.7.2/lib/binding_of_caller/mri2.rb:23:in `loop'
/Users/yyong/.rbenv/versions/2.2.1/lib/ruby/gems/2.2.0/gems/binding_of_caller-0.7.2/lib/binding_of_caller/mri2.rb:23:in `block in callers'
/Users/yyong/.rbenv/versions/2.2.1/lib/ruby/gems/2.2.0/gems/binding_of_caller-0.7.2/lib/binding_of_caller/mri2.rb:21:in `open'
/Users/yyong/.rbenv/versions/2.2.1/lib/ruby/gems/2.2.0/gems/binding_of_caller-0.7.2/lib/binding_of_caller/mri2.rb:21:in `callers'
/Users/yyong/.rbenv/versions/2.2.1/lib/ruby/gems/2.2.0/gems/better_errors-1.1.0/lib/better_errors/core_ext/exception.rb:9:in `block in <class:Exception>'
/Users/yyong/.rbenv/versions/2.2.1/lib/ruby/2.2.0/open-uri.rb:36:in `initialize'
/Users/yyong/.rbenv/versions/2.2.1/lib/ruby/2.2.0/open-uri.rb:36:in `open'
/Users/yyong/.rbenv/versions/2.2.1/lib/ruby/2.2.0/open-uri.rb:36:in `open'
/Users/yyong/.rbenv/versions/2.2.1/lib/ruby/2.2.0/logger.rb:628:in `open_logfile'
/Users/yyong/.rbenv/versions/2.2.1/lib/ruby/2.2.0/logger.rb:584:in `initialize'
/Users/yyong/.rbenv/versions/2.2.1/lib/ruby/2.2.0/logger.rb:318:in `new'
/Users/yyong/.rbenv/versions/2.2.1/lib/ruby/2.2.0/logger.rb:318:in `initialize'
/Users/yyong/.rbenv/versions/2.2.1/lib/ruby/gems/2.2.0/gems/daemons-1.1.9/lib/daemons/application.rb:353:in `new'
/Users/yyong/.rbenv/versions/2.2.1/lib/ruby/gems/2.2.0/gems/daemons-1.1.9/lib/daemons/application.rb:353:in `exception_log'
/Users/yyong/.rbenv/versions/2.2.1/lib/ruby/gems/2.2.0/gems/daemons-1.1.9/lib/daemons/application.rb:165:in `block in start_load'
E, [2018-05-02T17:25:10.468792 #2734] ERROR -- : No such file or directory @ rb_sysopen - /Users/yyong/rbdev/peatio/log/payment_transaction.rb.log (Errno::ENOENT)
/Users/yyong/.rbenv/versions/2.2.1/lib/ruby/2.2.0/open-uri.rb:36:in `initialize'
/Users/yyong/.rbenv/versions/2.2.1/lib/ruby/2.2.0/open-uri.rb:36:in `open'
/Users/yyong/.rbenv/versions/2.2.1/lib/ruby/2.2.0/open-uri.rb:36:in `open'
/Users/yyong/.rbenv/versions/2.2.1/lib/ruby/2.2.0/logger.rb:628:in `open_logfile'
/Users/yyong/.rbenv/versions/2.2.1/lib/ruby/2.2.0/logger.rb:584:in `initialize'
/Users/yyong/.rbenv/versions/2.2.1/lib/ruby/2.2.0/logger.rb:318:in `new'
/Users/yyong/.rbenv/versions/2.2.1/lib/ruby/2.2.0/logger.rb:318:in `initialize'
/Users/yyong/.rbenv/versions/2.2.1/lib/ruby/gems/2.2.0/gems/daemons-1.1.9/lib/daemons/application.rb:353:in `new'
/Users/yyong/.rbenv/versions/2.2.1/lib/ruby/gems/2.2.0/gems/daemons-1.1.9/lib/daemons/application.rb:353:in `exception_log'
/Users/yyong/.rbenv/versions/2.2.1/lib/ruby/gems/2.2.0/gems/daemons-1.1.9/lib/daemons/application.rb:165:in `block in start_load'
I, [2018-05-02T17:38:23.093153 #15771]  INFO -- : *** below you find the most recent exception thrown, this will be likely (but not certainly) the exception that made the application exit abnormally ***
E, [2018-05-02T17:38:23.095619 #15771] ERROR -- : Value will be available once the pipeline executes. (Redis::FutureNotReady)

I, [2018-05-02T17:38:23.096320 #15771]  INFO -- : *** below you find all exception objects found in memory, some of them may have been thrown in your application, others may just be in memory because they are standard exceptions ***
E, [2018-05-02T17:38:23.098195 #15771] ERROR -- : stream closed (IOError)

E, [2018-05-02T17:38:23.100715 #15771] ERROR -- : failed to allocate memory (NoMemoryError)

E, [2018-05-02T17:38:23.100956 #15771] ERROR -- : stack level too deep (SystemStackError)

E, [2018-05-02T17:38:23.101675 #15771] ERROR -- : exception reentered (fatal)

E, [2018-05-02T17:38:23.171148 #15771] ERROR -- : Value will be available once the pipeline executes. (Redis::FutureNotReady)

I, [2018-05-10T15:14:54.902591 #19197]  INFO -- : *** below you find the most recent exception thrown, this will be likely (but not certainly) the exception that made the application exit abnormally ***
E, [2018-05-10T15:14:54.907671 #19197] ERROR -- : Value will be available once the pipeline executes. (Redis::FutureNotReady)

I, [2018-05-10T15:14:54.908037 #19197]  INFO -- : *** below you find all exception objects found in memory, some of them may have been thrown in your application, others may just be in memory because they are standard exceptions ***
E, [2018-05-10T15:14:54.908817 #19197] ERROR -- : stream closed (IOError)

E, [2018-05-10T15:14:54.911861 #19197] ERROR -- : failed to allocate memory (NoMemoryError)

E, [2018-05-10T15:14:54.912130 #19197] ERROR -- : stack level too deep (SystemStackError)

E, [2018-05-10T15:14:54.914647 #19197] ERROR -- : exception reentered (fatal)

E, [2018-05-10T15:14:55.138132 #19197] ERROR -- : Value will be available once the pipeline executes. (Redis::FutureNotReady)

